Workbook
Name Add_SALT: 'Sch. A'!$AI$37
Name Additional_Income: 'Sch. 1'!$AC$56
Name AdditionalCTC: '8812'!$AL$85
Name Address: '1040'!$B$13
Name Adj_Gross_Inc: '1040'!$AL$79
Name Adj_Gross_Inc_Pg2: '1040'!$AL$82
Name AdjustToIncome: 'Sch. 1'!$AC$100
Name AdoptCredit: 'Sch. 3'!$W$20
Name AgPMT_Disaster: '1099-G'!$J$31
Name AgPMT_Other: '1099-G'!$J$32
Name Alaska: '1040'!$BN$10
Name Alien_Spouse: '1040'!$F$27
Name AlienSpouseName: '1040'!$AA$28
Name AlimonyPaid: 'Sch. 1'!$AJ$70
Name AlimonyRcvd: 'Sch. 1'!$AC$16
Name AltMinTaxInc: '6251'!$M$39
Name AMT: '6251'!$R$64
Name AMTExemption: '6251'!$AC$172
Name AMTExemptionFlag: '6251'!$AH$80
Name AO_Credit: '8863'!$AE$33
Name AOC_1: '8863'!$AE$110
Name AOC_2: '8863'!$AE$168
Name AOC_3: '8863'!$AE$226
Name AOC_4: '8863'!$AE$284
Name Apt_No.: '1040'!$AD$13
Name ArcherMSADeduct: 'Sch. 1'!$AC$77
Name BadBirthdate_Spouse: '1040'!$BK$144
Name BadBirthdate_Yours: '1040'!$BK$123
Name BadDeathDate: '1040'!$BR$144
Name BASE_A1: 'Tax Table'!$U$7
Name BASE_A2: 'Tax Table'!$U$8
Name BASE_A3: 'Tax Table'!$U$9
Name BASE_A4: 'Tax Table'!$U$10
Name BASE_A5: 'Tax Table'!$U$11
Name BASE_A6: 'Tax Table'!$U$12
Name BASE_A7: 'Tax Table'!$U$13
Name BASE_B1: 'Tax Table'!$U$17
Name BASE_B2: 'Tax Table'!$U$18
Name BASE_B3: 'Tax Table'!$U$19
Name BASE_B4: 'Tax Table'!$U$20
Name BASE_B5: 'Tax Table'!$U$21
Name BASE_B6: 'Tax Table'!$U$22
Name BASE_B7: 'Tax Table'!$U$23
Name BASE_C1: 'Tax Table'!$U$27
Name BASE_C2: 'Tax Table'!$U$28
Name BASE_C3: 'Tax Table'!$U$29
Name BASE_C4: 'Tax Table'!$U$30
Name BASE_C5: 'Tax Table'!$U$31
Name BASE_C6: 'Tax Table'!$U$32
Name BASE_C7: 'Tax Table'!$U$33
Name BASE_D1: 'Tax Table'!$U$38
Name BASE_D2: 'Tax Table'!$U$39
Name BASE_D3: 'Tax Table'!$U$40
Name BASE_D4: 'Tax Table'!$U$41
Name BASE_D5: 'Tax Table'!$U$42
Name BASE_D6: 'Tax Table'!$U$43
Name BASE_D7: 'Tax Table'!$U$44
Name BeginningOfTaxYear: '1040'!$BI$2
Name Birthday_Needed: '1040'!$BI$136
Name BOTT_A1: 'Tax Table'!$T$7

Sheet 1040
C1: =RevDateTime | H1: NOTE: Check every calculation carefully!!! | AH1: =IF('Table of Contents'!A19="D","DRAFT FORM","") | AU1: =IF(File_Single<>"",1,0) | BT1: Notes
C2: =RevDateTime | H2: www.excel1040.com | AH2: ="© Glenn Reeves, "&TaxYear+1 | AU2: =IF(File_Marr_Joint<>"",1,0) | AW2: Check here to remove blue & green colors from all sheets. | BA2: =(AV2<>"") | BI2: =DATEVALUE("1-JAN-"&TaxYear) | BJ2: =IF(BL2>365,TRUE,FALSE) | BK2: =DATEVALUE("1-JAN-"&TaxYear+1)-1 | BL2: =EndOfTaxYear+1-BeginningOfTaxYear | BN2: Alaska | BO2: Hawaii | BP2: Maine | BQ2: Mass. | BR2: D.C. | BT2: Date
B3: Form | C3: 1040 | G3: =IF(FilingStatusError,"Please check only ONE filing status box.","Department of the Treasury––Internal Revenue Service") | X3: 2025 | AH3: =IF(AND(AT3="",'Table of Contents'!A19="D"),"DRAFT FORM","") | AU3: =IF(File_Marr_Sep<>"",1,0) | AW3: Check here to hide Social Security numbers on forms. | BA3: =(AV3<>"") | BF3: =TaxYear-1 | BN3: =IF(ISERROR(FIND("ALASKA",State)),FALSE,TRUE) | BO3: =IF(ISERROR(FIND("HAWAII",State)),FALSE,TRUE) | BP3: =IF(ISERROR(FIND("MAINE",State)),FALSE,TRUE) | BQ3: =IF(ISERROR(FIND("MASSACHUSETTS",State)),FALSE,TRUE) | BR3: =IF(ISERROR(FIND("DISTRICT",State)),FALSE,TRUE)
F4: =IF(NumFileStatusBoxes=0,"Check one FILING STATUS box.","U.S. Individual Income Tax Return") | AC4: OMB No. 1545-0074 | AH4: =IF(FilingStatusError,"Check only ONE filing status block","IRS Use Only—Do not write or staple in this space.") | AU4: =IF(File_Head<>"",1,0) | AV4: Filing Status: | AX4: =IF(NumFileStatusBoxes=0,"Filing status not indicated.",IF(FilingStatusError,"Check only ONE filing status box.",IF(File_Single<>"","Single",IF(File_Marr_Joint<>"","Married - Filing Jointly",IF(File_Marr_Sep<>"","Married - Filing Separately",IF(File_Head<>"","Head of Household",IF(File_Qual_Widow<>"","Qualifying Widow(er)",""))))))) | BF4: =TaxYear+1 | BN4: =IF(ISERROR(FIND("AK",State)),FALSE,TRUE) | BO4: =IF(ISERROR(FIND("HI",State)),FALSE,TRUE) | BP4: =IF(ISERROR(FIND("ME",State)),FALSE,TRUE) | BQ4: =IF(ISERROR(FIND("MA",State)),FALSE,TRUE) | BR4: =IF(ISERROR(FIND("DC",State)),FALSE,TRUE)
B5: ="For the year Jan. 1–Dec. 31, "&TaxYear&", or other tax year beginning" | Y5: ending | AH5: See separate instructions.
C6: Filed pursuant to section 301.9100-2 | N6: Combat zone | AC6: Deceased | AK6: Spouse
C7: Other | AW7: =IF(File_Marr_Sep<>""," Yes.","") | AX7: =IF(File_Marr_Sep<>"","Did you live apart from your spouse for all of "&TEXT(TaxYear,"0")&"?","") | BB7: =AND(File_Marr_Sep<>"",OR(AV7<>"",AV8<>""))
C8: Your first name and middle initial | R8: =IF(AND(File_Marr_Sep<>"",OR(NOT(LivedApartAnswered),N25="")),"Please answer questions at right regarding your spouse."," Last name") | AH8: Your social security number | AW8: =IF(OR(AND(AV7<>"",AV8<>""),AND(File_Marr_Sep<>"",AV7="",AV8=""))," No.",IF(File_Marr_Sep<>""," No.","")) | AX8: =IF(OR(AND(AV7<>"",AV8<>""),AND(File_Marr_Sep<>"",AV7="",AV8="")),"Please check ONE box.","") | BB8: =AND(File_Marr_Sep<>"",AV7<>"")
AH9: 1010001 | AU9: =IF(File_Qual_Widow<>"",1,0) | AW9: =IF(File_Marr_Sep<>"","Check here if your spouse had no income and is NOT filing a tax return.","") | BN9: =IF(ISERROR(FIND("Alaska",State)),FALSE,TRUE) | BO9: =IF(ISERROR(FIND("Hawaii",State)),FALSE,TRUE) | BP9: =IF(ISERROR(FIND("Maine",State)),FALSE,TRUE) | BQ9: =IF(ISERROR(FIND("Massachusetts",State)),FALSE,TRUE) | BR9: =IF(ISERROR(FIND("D.C.",State)),FALSE,TRUE)
C10: If joint return, spouse's first name and middle initial | R10: Last name | AH10: =IF(AND(File_Marr_Sep<>"",SS_Spouse=""),"Enter spouse's Soc. Sec. number","Spouse's social security number") | AU10: =SUM(AU1:AU9) | BC10: =AND(DependentYOU="",OR(File_Single<>"",File_Marr_Joint<>"",File_Marr_Sep<>"",File_Head<>"",File_Qual_Widow<>"")) | BN10: =OR(BN3,BN4,BN9) | BO10: =OR(BO3,BO4,BO9) | BP10: =OR(BP3,BP4,BP9) | BQ10: =OR(BQ3,BQ4,BQ9) | BR10: =OR(BR3,BR4,BR9)
AH11: =IF(NumFileStatusBoxes=0,"Filing status?",1010002) | AU11: =NumFileStatusBoxes>1 | BG11: =IF(AND(Name_1st_Yours<>"",Name_1st_Sp<>""),Name_1st_Yours&" "&Name_Last_Yours&" & "&Name_1st_Sp&" "&Name_Last_Sp,IF(Name_Last_Yours<>"",Name_1st_Yours&" "&Name_Last_Yours,"")) | BQ11: =OR(BP10,BQ10,BR10)
C12: Home address (number and street). If you have a P.O. box, see instructions. | AD12: Apt. no. | AH12: Check here if your main home, and your spouse's, | AU12: =(NumFileStatusBoxes>1) | BF12: =AND(OR(File_Single<>"",File_Head<>""),OR(sp_over_64<>"",sp_blind<>"",DependentSPOUSE<>"",Dual_Status_Alien<>"")) | BQ12: For 'Patriots' Day or
AH13: ="if filing a joint return, was in the U.S. for more than half of "&TaxYear&"." | AS13: X | AU13: =IF(AND(OR(File_Single<>"",File_Head<>""),OR(sp_over_64<>"",sp_blind<>"")),TRUE,FALSE) | AW13: =IF(AND($BF$13,BI15,BI17),"Birthdates",IF($BF$13,"Enter your birthdate and your spouse's birthdate.",IF(BI15,"Birthdate","Enter your birthdate."))) | BF13: =OR(File_Marr_Joint<>"",File_Marr_Sep<>"",File_Qual_Widow<>"") | BG13: =Name_1st_Yours&" "&Name_Last_Yours | BI13: =Name_1st_Sp&" "&Name_Last_Sp | BQ13: Emancipation Day (D.C.)
C14: City, town, or post office. If you have a foreign address, also complete spaces below. | X14: State | AC14: ZIP Code | AH14: Presidential Election Campaign | AX14: Month (e.g. '11') | AY14: Day (e.g. '9') | AZ14: Year (e.g. '1997') | BF14: =IF(you_over_64<>"",1,0) | BG14: You > 64
AH15: Check here if you, or your spouse if filing jointly, want $3 to go to this fund. Checking a box below will not change your tax or refund. | AW15: You | BF15: =IF(you_blind<>"",1,0) | BG15: You blind | BI15: =AND(YourBirthMonth<>"",YourBirthDay<>"",YourBirthYear<>"") | BJ15: =IF(OR(YourBirthMonth="",YourBirthDay="",YourBirthYear=""),"Enter your birthdate",IF(BL123,"Your birthdate appears to be in error.",IF(BI16,"For IRS purposes, you were "&YourAge&" years old on December 31, "&TaxYear&".","You were "&YourAge&" years old on December 31, "&TaxYear&".")))
C16: Foreign country name | S16: Foreign province/state/county | AC16: Foreign postal code | AX16: =BJ15 | BF16: =IF(AND(OR(File_Marr_Joint<>"",SpouseSep_NoIncome),sp_over_64<>""),1,0) | BG16: Spouse > 64 | BI16: =AND(YourBirthMonth=1,YourBirthDay=1)
AK17: You | AO17: Spouse | AW17: =IF($BF$13,"Spouse ","") | BF17: =IF(AND(OR(File_Marr_Joint<>"",SpouseSep_NoIncome),sp_blind<>""),1,0) | BG17: Spouse blind | BI17: =AND(OR(File_Marr_Sep<>"",File_Marr_Joint<>""),SpouseBirthMonth<>"",SpouseBirthDay<>"",SpouseBirthYear<>"") | BJ17: =IF(AND(File_Marr_Sep="",File_Marr_Joint=""),"",IF(AND(OR(File_Marr_Sep<>"",File_Marr_Joint<>""),OR(SpouseBirthMonth="",SpouseBirthDay="",SpouseBirthYear="")),"Enter spouse's birthdate.",IF(BL144,"Spouse's birthdate appears to be in error.",IF(BI22,"For IRS purposes, you were "&SpouseAge&" years old on December 31, "&TaxYear&".","Your spouse was "&SpouseAge&" years old on December 31, "&TaxYear&"."))))
AV18: =IF(File_Marr_Joint<>"","Check "&CHAR(10)&"if deceased","") | AX18: =BJ17
B20: Filing Status | G20: Single | AC20: Head of Household (HOH) | BF20: =IF(OR(AND(OR(File_Single<>"",File_Head<>""),OR(sp_over_64<>"",sp_blind<>"")),NumFileStatusBoxes=0),0,SUM(BF14:BF17)) | BG20: Total | BI20: =AND(File_Marr_Sep<>"",MFS_Spouse_NotFiling<>"",DependentSPOUSE="")
B22: Check only one box | G22: Married filing jointly (even if only one had income) | AC22: Qualifying Surviving Spouse (QSS) | AW22: =IF(AW24,"Date of death ","") | BI22: =AND(SpouseBirthMonth=1,SpouseBirthDay=1)
AB23: If you checked the HOH or QSS box, enter the child’s name if the qualifying person is a child but not your dependent: | AX23: =IF(AND(SpouseDeceased<>"",OR(SpouseDeathMonth="",SpouseDeathDay="",SpouseDeathYear="")),"Enter date of spouse's death.",IF(AW25,"Spouse must have lived during "&TaxYear&" tax year.",IF(BadDeathDate,"The date of death appears to be in error.","")))
G24: Married filing separately (MFS) Enter spouse's SSN above | AW24: =AND($AV$17<>"",$BF$13) | BI24: =AND($AW$24,SpouseAge>65) | BJ24: Deceased spouse was >65 years old.
G25: and full name here: | AW25: =AND(SpouseDeceased<>"",SpouseDeathYear<>"",SpouseDeathYear<>TaxYear) | BI25: =AND($AW$24,SpouseAge=65) | BJ25: Deceased turned 65 years old during tax year.
G27: If treating a nonresident alien or dual-status alien spouse as a U.S. resident for the entire tax year, check the box and enter their | BI27: =AND($AW$24,OR(SpouseDeathMonth<SpouseBirthMonth,AND(SpouseDeathMonth=SpouseBirthMonth,SpouseDeathDay<SpouseBirthDay))) | BJ27: Spouse passed way before birthday
G28: name (see instructions and attach statement if required): | BI28: =OR(BI24,AND(BI25,NOT(BI27))) | BJ28: Deceased spouse std. deduct. Credit for >64
B30: Digital Assets | F30: ="At any time during "&TaxYear&", did you (a) receive (as a reward, award, or payment for property or service); or (b) sell, "&CHAR(10)&"exchange, gift, or otherwise dispose of a digital asset (or a financial interest in a digital asset)? (See instructions.)"
AN31: Yes | AR31: No | AU31: =IF(AND(DigitalAsset_Yes="",DigitalAsset_No=""),"<< Check one.","")
B33: Dependents | L33: Dependent 1 | U33: Dependent 2 | AD33: Dependent 3 | AL33: Dependent 4 | AU33: Enter information for dependents on the 'Dependents' sheet.
B34: (see instructions) | F34: (1) First name | L34: =IF(Dependents!E7="","",Dependents!E7) | U34: =IF(Dependents!E8="","",Dependents!E8) | AD34: =IF(Dependents!E9="","",Dependents!E9) | AL34: =IF(Dependents!E10="","",Dependents!E10) | BB34: =IF(M47<>"",1,0) | BC34: =(AND(L34<>"",L35<>"",M47="",Q47="")) | BE34: =IF(M47<>"",1,0)
F35: (2) Last name | L35: =IF(Dependents!I7="","",Dependents!I7) | U35: =IF(Dependents!I8="","",Dependents!I8) | AD35: =IF(Dependents!I9="","",Dependents!I9) | AL35: =IF(Dependents!I10="","",Dependents!I10) | BB35: =IF(V47<>"",1,0) | BC35: =(AND(U34<>"",U35<>"",V47="",Z47="")) | BD35: =OR(BC34,BC35,BC36,BC37) | BE35: =IF(V47<>"",1,0)
B36: If more than four dependents, see instructions and check here . . . . | F36: (3) SSN | L36: =IF(Dependents!M7="","",Dependents!M7) | U36: =IF(Dependents!M8="","",Dependents!M8) | AD36: =IF(Dependents!M9="","",Dependents!M9) | AL36: =IF(Dependents!M10="","",Dependents!M10) | BB36: =IF(AE47<>"",1,0) | BC36: =(AND(AD34<>"",AD35<>"",AE47="",AI47="")) | BD36: =IF(DependentYOU="",1,0) | BE36: =IF(AE47<>"",1,0)
F37: (4) Relationship | L37: =IF(Dependents!S7="","",Dependents!S7) | U37: =IF(Dependents!S8="","",Dependents!S8) | AD37: =IF(Dependents!S9="","",Dependents!S9) | AL37: =IF(Dependents!S10="","",Dependents!S10) | BB37: =IF(AM47<>"",1,0) | BC37: =(AND(AL34<>"",AL35<>"",AM47="",AQ47="")) | BD37: =IF(AND(File_Marr_Joint<>"",DependentSPOUSE=""),1,0) | BE37: =IF(AM47<>"",1,0)
F38: (5) Check if lived with you more than
N39: (a) | O39: =IF(Dependents!Z7="","","X") | P39: Yes | W39: (a) | X39: =IF(Dependents!Z8="","","X") | Y39: Yes | AE39: (a) | AF39: =IF(Dependents!Z9="","","X") | AG39: Yes | AM39: (a) | AN39: =IF(Dependents!Z10="","","X") | AO39: Yes
D41: =IF(DependentsGT4,"X","") | F41: ="than half of "&TaxYear | N41: (b) | O41: =IF(Dependents!AC7="","","X") | P41: And in the U.S. | W41: (b) | X41: =IF(Dependents!AC8="","","X") | Y41: And in the U.S. | AE41: (b) | AF41: =IF(Dependents!AC9="","","X") | AG41: And in the U.S. | AM41: (b) | AN41: =IF(Dependents!AC10="","","X") | AO41: And in the U.S. | AZ41: =IF(OR(NumFileStatusBoxes=0,NumFileStatusBoxes>1),0,SUM(BD36,BD37,AW47,AW48)) | BA41: Tax Family Size (for Form 8962, Premium Tax Credit)
AZ42: Determine the number of individuals in your tax family using your tax return. Your tax family generally includes you, your spouse if you are filing a joint return, and your dependents. If you checked the “Someone can claim you as a dependent” box, or if you’re filing jointly and you checked the “Someone can claim your spouse as a dependent” box on your tax return, you or your spouse are not included in the tax family size calculation for purposes of Form 8962, Premium Tax Credit, line 1.
F43: (6) Check if | AN43: Full-time student
M44: =IF(Dependents!AF7="","","X") | N44: Full-time student | Q44: =IF(Dependents!AI7="","","X") | R44: Permanently and totally disabled | V44: =IF(Dependents!AF8="","","X") | W44: Full-time student | Z44: =IF(Dependents!AI8="","","X") | AA44: Permanently and totally disabled | AE44: =IF(Dependents!AF9="","","X") | AF44: Full-time student | AI44: =IF(Dependents!AI9="","","X") | AJ44: Permanently and totally disabled | AM44: =IF(Dependents!AF10="","","X") | AQ44: =IF(Dependents!AI10="","","X") | AR44: Permanently and totally disabled
F46: (7) Credits | AN46: Child tax credit
M47: =IF(Dependents!BB7="","","X") | N47: Child tax credit | Q47: =IF(Dependents!BK7="","","X") | R47: Credit for other dependents | V47: =IF(Dependents!BB8="","","X") | W47: Child tax credit | Z47: =IF(Dependents!BK8="","","X") | AA47: Credit for other dependents | AE47: =IF(Dependents!BB9="","","X") | AF47: Child tax credit | AI47: =IF(Dependents!BK9="","","X") | AJ47: Credit for other dependents | AM47: =IF(Dependents!BB10="","","X") | AQ47: =IF(Dependents!BK10="","","X") | AR47: Credit for other dependents | AW47: =Qual_Child_Count | AX47: Number of qualifying children.
...

Sheet Coversheet
B1: www.excel1040.com | D1: or | E1: https://sites.google.com/view/incometaxspreadsheet/home
B2: =IF(AND(TaxYearStart<>"",TaxYearEnd<>""),"For tax year "&TEXT(TaxYearStart,"mmm. d")&" - "&TEXT(TaxYearEnd,"mmm. dd, yyyy")&".","For tax year Jan. 1 - Dec. 31, "&TaxYear&".") | G2: Spreadsheet Revision Date/Time: | H2: =RevDateTime
B4: -- DISCLAIMER -- These spreadsheets are provided "as is", with no warranty of any kind, expressed or implied, and in no event will Glenn Reeves be liable for direct, indirect, incidental, or consequential damages resulting from the use of any of these spreadsheets. Glenn Reeves specifically disclaims the role of tax adviser. These spreadsheets attempt to perform the mechanics of tax preparation in accordance with IRS forms and instructions. The user must assume responsibility as to the correctness and appropriateness of any and all amounts entered and results produced.
B14: No password is needed. If you find a data entry cell to be protected, it is because it is a calculated value using input from another location in the spreadsheet. Read the instructions for that line to determine where the values are derived. However, for most calculated cells, a manual override cell is provided if you need to override the calculated value. After a while, you will figure out that the spreadsheet is completely functional without needing to unprotect it.
B24: Errors If you find an error, first check the revision date/time above against the revision number of the latest spreadsheet to be published at:
E26: https://sites.google.com/view/incometaxspreadsheet/home/changes
C27: If you find you're using an earlier version, review the changes made since your version
C28: to determine if the problem you've encountered has already been fixed.
C29: If so, please download the latest version and begin again. (There is no simple way to migrate...)
C30: If you cannot determine (or you're not sure) as to whether or not the problem(s) you've found
C31: has been corrected, please do your fellow taxpayers a favor by reporting the problem to:
E32: incometaxspreadsheet@gmail.com
B35: SUMMARY
B36: Adjusted Gross Income | E36: =Adj_Gross_Inc | G36: Form 1040, Line 11 | M36: Single | N36: =IF(Taxable_Inc="","---",IF(Taxable_Inc<BOTT_A2,TEXT(RATE_A1,"0%"),IF(Taxable_Inc<BOTT_A3,TEXT(RATE_A2,"0%"),IF(Taxable_Inc<BOTT_A4,TEXT(RATE_A3,"0%"),IF(Taxable_Inc<BOTT_A5,TEXT(RATE_A4,"0%"),IF(Taxable_Inc<BOTT_A6,TEXT(RATE_A5,"0%"),IF(Taxable_Inc<BOTT_A7,TEXT(RATE_A6,"0%"),TEXT(RATE_A7,"0.0%"))))))))
B37: Total Deductions | E37: =TotalDeductions | G37: Form 1040, Line 14
B38: Taxable Income | E38: =Taxable_Inc | G38: Form 1040, Line 15 | M38: MFJ or QW | N38: =IF(Taxable_Inc="","---",IF(Taxable_Inc<BOTT_B2,TEXT(RATE_B1,"0%"),IF(Taxable_Inc<BOTT_B3,TEXT(RATE_B2,"0%"),IF(Taxable_Inc<BOTT_B4,TEXT(RATE_B3,"0%"),IF(Taxable_Inc<BOTT_B5,TEXT(RATE_B4,"0%"),IF(Taxable_Inc<BOTT_B6,TEXT(RATE_B5,"0%"),IF(Taxable_Inc<BOTT_B7,TEXT(RATE_B6,"0%"),TEXT(RATE_B7,"0.0%"))))))))
B39: Total Tax | E39: =Tot_Tax | G39: Form 1040, Line 24 | M39: MFS | N39: =IF(Taxable_Inc="","---",IF(Taxable_Inc<BOTT_C2,TEXT(RATE_C1,"0%"),IF(Taxable_Inc<BOTT_C3,TEXT(RATE_C2,"0%"),IF(Taxable_Inc<BOTT_C4,TEXT(RATE_C3,"0%"),IF(Taxable_Inc<BOTT_C5,TEXT(RATE_C4,"0%"),IF(Taxable_Inc<BOTT_C6,TEXT(RATE_C5,"0%"),IF(Taxable_Inc<BOTT_C7,TEXT(RATE_C6,"0%"),TEXT(RATE_C7,"0.0%"))))))))
B40: Total Payments/Credits | E40: =Tot_Payments | G40: Form 1040, Line 33 | M40: HOH | N40: =IF(Taxable_Inc="","---",IF(Taxable_Inc<BOTT_D2,TEXT(RATE_D1,"0%"),IF(Taxable_Inc<BOTT_D3,TEXT(RATE_D2,"0%"),IF(Taxable_Inc<BOTT_D4,TEXT(RATE_D3,"0%"),IF(Taxable_Inc<BOTT_D5,TEXT(RATE_D4,"0%"),IF(Taxable_Inc<BOTT_D6,TEXT(RATE_D5,"0%"),IF(Taxable_Inc<BOTT_D7,TEXT(RATE_D6,"0%"),TEXT(RATE_D7,"0.0%"))))))))
B41: =IF(Overpaid>0,"Amount You Overpaid",IF(AND(E41<>"",E41>0),"Amount You Underpaid","")) | E41: =IF(Overpaid>0,Overpaid,IF(SUM(Tot_Tax,-Tot_Payments)>0,SUM(Tot_Tax,-Tot_Payments),"")) | G41: =IF(Overpaid>0,"Form 1040, Line 34","")
B42: =IF(TaxPenalty>0,"Penalty/Interest","") | E42: =IF(TaxPenalty>0,TaxPenalty,"") | G42: =IF(TaxPenalty>0,"Form 1040, Line 38","")
B43: =IF(Overpaid>0,"Amount To be Refunded","Amount You Owe") | E43: =IF('1040'!AL126>0,'1040'!AL126,You_Owe) | G43: =IF(Overpaid>0,"Form 1040, Line 35a","Form 1040, Line 37")
B44: =IF(AND('1040'!AD129<>"",'1040'!AD129>0),"Amount applied to your "&TaxYear+1&" estimated tax","") | E44: =IF(AND('1040'!AD129<>"",'1040'!AD129>1000),TEXT('1040'!AD129,"$0,000"),IF(AND('1040'!AD129<>"",'1040'!AD129>0),TEXT('1040'!AD129,"$0"),"")) | G44: =IF(AND('1040'!AD129<>"",'1040'!AD129>0),"Form 1040, Line 36","")
B46: Tax Bracket | E46: =IF(File_Single<>"",N36,IF(OR(File_Marr_Joint<>"",File_Qual_Widow<>""),N38,IF(File_Marr_Sep<>"",N39,IF(File_Head<>"",N40,"---"))))
B47: Effective Tax Rate | E47: =IF(E36=0,"---",E39/E36)
B51: This spreadsheet is free. However, if you would like to show your appreciation, you may make a contribution by clicking one of the following links and sending money as indicated.
C56: PayPal | E56: Zelle (App)
C57: https://paypal.me/incometaxspreadsheet | E57: https://www.zellepay.com/
C58: (Send to: IncomeTaxSpreadsheet@gmail.com ) | E58: (Send to: IncomeTaxSpreadsheet@gmail.com )
C60: Google Pay | E60: Venmo
C61: https://pay.google.com/payments/ | E61: https://www.venmo.com
C62: (Send to: IncomeTaxSpreadsheet@gmail.com ) | E62: (Send to: @Glenn-Reeves-2 )
C64: US Mail:
C65: Glenn Reeves
C66: (Tax Calculator)
C67: 4802 N 124th Ct
C68: Kansas City, KS 66109-3809
D70: Thank you for using my spreadsheet and for any money you decide to send!

Sheet Table of Contents
A2: Draft / Final | B2: Sheet Name (with hyperlink)
C3: Federal Income Tax Spreadsheet
C4: Table of Contents | G4: Draft IRS | H4: Final IRS | I4: Draft IRS | J4: Final IRS | K4: Updated | L4: Updated
C5: ="© Glenn Reeves, "&TaxYear+1 | F5: Form | G5: Instruction | H5: Instruction | I5: Form | J5: Form | K5: Draft Form | L5: Final
C6: Title / Description | F6: Last checked | G6: =MAX(G7:L72)
A7: =IF(L7<>"","F",IF(K7<>"","D","")) | B7: Coversheet | C7: Possible tax return coversheet which includes a disclaimer, important notes, and a summary.
A8: =IF(L8<>"","F",IF(K8<>"","D","")) | B8: Table of Contents | C8: Table of contents with links to the sheets included in this spreadsheet.
A9: =IF(L9<>"","F",IF(K9<>"","D","")) | B9: Instructions | C9: Important notes, general notes, and instructions to help you get started.
A10: =IF(L10<>"","F",IF(K10<>"","D","")) | B10: W-2s | C10: Form W-2, Wage and Tax Statement | E10: 1 | F10: =B10
A11: =IF(L11<>"","F",IF(K11<>"","D","")) | B11: 1099-INT | C11: Form 1099-INT, Interest Income | E11: 2 | F11: =B11
A12: =IF(L12<>"","F",IF(K12<>"","D","")) | B12: 1099-DIV | C12: Form 1099-DIV, Dividend Income | E12: 3 | F12: =B12
A13: =IF(L13<>"","F",IF(K13<>"","D","")) | B13: 1099-G | C13: Form 1099-G, Certain Government Payments | E13: 4 | F13: =B13
A14: =IF(L14<>"","F",IF(K14<>"","D","")) | B14: 1099-MISC | C14: Form 1099-MISC, Miscellaneous Income (Way too complicated -- included for information) | E14: 5 | F14: =B14
A15: =IF(L15<>"","F",IF(K15<>"","D","")) | B15: 1099-NEC | C15: Form 1099-NEC, Nonemployee Compensation | E15: 6 | F15: =B15
A16: =IF(L16<>"","F",IF(K16<>"","D","")) | B16: 1099-R | C16: Form 1099-R, Distributions From Pensions, Annuities, Retirement or Profit-Sharing Plans, IRAs, Insurance Contracts, etc. | E16: 7 | F16: =B16
A17: =IF(L17<>"","F",IF(K17<>"","D","")) | B17: Lines 4ab (IRA Dist.) | C17: IRA Distributions -- Lines 4a and 4b -- to determine how to report non-taxable and taxable IRA distributions. | E17: 8 | F17: =B17
A18: =IF(L18<>"","F",IF(K18<>"","D","")) | B18: SSA-1099 | C18: Form SSA-1099, Social Security Benefit Statement and IRS Notice 703, To See If Your Social Security Benefits May Be Taxable | E18: 9 | F18: =B18
A19: =IF(L19<>"","F",IF(K19<>"","D","")) | B19: 1040 | C19: Form 1040, U.S. Individual Income Tax Return | E19: 10 | F19: =B19 | G19: 45999 | I19: 45996 | J19: 46024 | K19: 45922 | L19: 46026
A20: =IF(L20<>"","F",IF(K20<>"","D","")) | B20: Sch. 1 | C20: Schedule 1, Additional Income and Adjustments to Income | E20: 11 | F20: =B20 | G20: 45999 | H20: 45733 | K20: 45991 | L20: 46026
A21: =IF(L21<>"","F",IF(K21<>"","D","")) | B21: Sch. 1-A | C21: Schedule 1-A, Additional Deductions | E21: 12 | F21: Sch. 1-A | G21: 45999 | I21: 45918 | K21: 45918 | L21: 46026
A22: =IF(L22<>"","F",IF(K22<>"","D","")) | B22: Sch 1, Line 1 (SALT) | C22: State and Local Income Tax Refund Worksheet — Line 1 | E22: 13 | F22: =B22 | G22: 45999 | K22: 45990 | L22: 46030 | N22: Tie lines 5 and 6 to previous year standard deduction amounts.
A23: =IF(L23<>"","F",IF(K23<>"","D","")) | B23: Sch. 1 Line 20 (IRA) | C23: IRA Deduction Worksheet — Schedule 1, Line 20 | E23: 14 | F23: =B23 | G23: 45999 | K23: 45990 | L23: 46030 | N23: Update line 1b limits and line 2 IRA deduction amounts
A24: =IF(L24<>"","F",IF(K24<>"","D","")) | B24: Sch. 1 Line 21 (Stu Loan) | C24: Student Loan Interest Deduction Worksheet — Schedule 1, Line 21 | E24: 15 | F24: =B24 | G24: 45999 | K24: 46009 | L24: 46030
A25: =IF(L25<>"","F",IF(K25<>"","D","")) | B25: Sch. 2 | C25: Schedule 2, Additional Taxes | E25: 16 | F25: =B25 | G25: 45999 | H25: 45785 | K25: 45862 | L25: 46026
A26: =IF(L26<>"","F",IF(K26<>"","D","")) | B26: Sch. 3 | C26: Schedule 3, Additional Credits and Payments | E26: 17 | F26: =B26 | G26: 45999 | H26: 45785 | I26: 45862 | K26: 46026 | L26: 46027
A27: =IF(L27<>"","F",IF(K27<>"","D","")) | B27: Earned Inc WS | C27: Earned Income Worksheet — Used as input to Line 9 (SD Depnts), Line 13a (CTC), & Form 8812. | E27: 18 | F27: =B27
A28: =IF(L28<>"","F",IF(K28<>"","D","")) | B28: Lines 5ab (Simplified Meth WS) | C28: Simplified Method Worksheet—Lines 5a and 5b -- to determine taxable amount of retirement pension or annuity. | E28: 19 | F28: =B28 | G28: 45999 | I28: 45980 | K28: 45988 | L28: 46030
A29: =IF(L29<>"","F",IF(K29<>"","D","")) | B29: Line 6ab (SS Bene) | C29: Social Security Benefits Worksheet – Lines 6a and 6b -- to determine taxable amount of Social Security benefits. | E29: 20 | F29: =B29 | G29: 45999 | K29: 45989 | L29: 46030
A30: =IF(L30<>"","F",IF(K30<>"","D","")) | B30: Line 12e (SD Depnts) | C30: Standard Deduction Worksheet for Dependents — Line 12e | E30: 21 | F30: =B30 | G30: 45999 | K30: 45990 | L30: 46030 | N30: Check lines 2 and 3 for amount changes.
A31: =IF(L31<>"","F",IF(K31<>"","D","")) | B31: Line 16 (QDCG Tax) | C31: Qualified Dividends and Capital Gain Tax Worksheet—Line 16 | E31: 22 | F31: =B31 | G31: 45999 | K31: 45990 | L31: 46030 | N31: Check lines 6 and 13 for amount changes.
A32: =IF(L32<>"","F",IF(K32<>"","D","")) | B32: Line 27a (EIC) | C32: Line 27a — Earned Income Credit Worksheet — Spreadsheet provides assistance in completing this. | E32: 23 | F32: =B32 | G32: 45999 | L32: 46038 | N32: Check Step 2, line 2, for amount changes. Check Worksheet A, Part 2, line 5, for amount changes.
A33: =IF(L33<>"","F",IF(K33<>"","D","")) | B33: Sch. A | C33: Schedule A, Itemized Deductions | E33: 24 | F33: =B33 | G33: 45992 | H33: 46009 | I33: 45911 | J33: 46008 | K33: 46014 | L33: 46020
A34: =IF(L34<>"","F",IF(K34<>"","D","")) | B34: Sch. B | C34: Schedule B, Interest and Ordinary Dividends | E34: 25 | F34: =B34 | G34: 45770 | I34: 45784 | K34: 45955 | L34: 46030
A35: =IF(L35<>"","F",IF(K35<>"","D","")) | B35: Sch. C | C35: Schedule C, Profit or Loss from Business (Two Schedule C's are included) | E35: 26 | F35: =B35 | G35: 45985 | H35: 46028 | I35: 45756 | J35: 46028 | L35: 46029
A36: =IF(L36<>"","F",IF(K36<>"","D","")) | B36: Sch. D | C36: Schedule D, Capital Gains and Losses | E36: 27 | F36: =B36 | G36: 46002 | H36: 46002 | I36: 45936 | J36: 46008 | K36: 45983 | L36: 46021
A37: =IF(L37<>"","F",IF(K37<>"","D","")) | B37: Sch. D WS | C37: Schedule D Worksheets - Capital Loss Carryover Worksheet—Schedule D, Lines 6 and 14 - 28% Rate Gain Worksheet—Schedule D, Line 18 - Schedule D Tax Worksheet | E37: 28 | F37: =B37 | G37: 46002 | H37: 46002 | L37: 46021
A38: =IF(L38<>"","F",IF(K38<>"","D","")) | B38: Sch. E | C38: Schedule E, Supplemental Income and Loss (2 forms) | E38: 29 | F38: =B38 | H38: 46009 | I38: 45783 | J38: 46009 | L38: 46021
A39: =IF(L39<>"","F",IF(K39<>"","D","")) | B39: Sch. E (2) | C39: Schedule E, Supplemental Income and Loss (2 forms) | E39: 30 | F39: =B39 | H39: 46009 | I39: 45783 | J39: 46009 | L39: 46021
A40: =IF(L40<>"","F",IF(K40<>"","D","")) | B40: Sch. F | C40: Schedule F, Profit or Loss from Farming | E40: 31 | F40: =B40 | G40: 45987 | H40: 46009 | I40: 45783 | J40: 46009 | L40: 46021
A41: =IF(L41<>"","F",IF(K41<>"","D","")) | B41: Sch. R | C41: Schedule R, Credit for the Elderly or the Disabled | E41: 32 | F41: =B41 | I41: 45931 | J41: 45933 | L41: 46030
...

Sheet Instructions
A2: Excel1040 -- Income Tax Spreadsheet
A3: Instructions for Use
B5: IMPORTANT NOTES:
B6: 1. | C6: The purpose of this spreadsheet is to help U.S. taxpayers calculate their own federal income tax returns.
C7: The spreadsheet attempts to perform the mechanics of tax preparation (i.e. 'do the math') in accordance
C8: with IRS forms and instructions.
B10: 2. | C10: This spreadsheet is designed for taxpayers who are capable of preparing their own federal income tax returns.
C11: Users of this spreadsheet must know what information needs to be entered and where to enter it.
C12: Users of this spreadsheet must also be sufficiently familiar with the IRS forms and instructions that apply to
C13: their tax return in order to detect and correct any and all user and spreadsheet errors that might occur.
C14: Although some error checking is included, this spreadsheet will not prevent you from making mistakes.
B16: 3. | C16: The user must assume full responsibility as to the correctness and appropriateness of any and all amounts
C17: entered and results produced. Be sure to use current copies of actual IRS forms and instructions when
C18: validating the spreadsheet's results. | H18: IRS forms and instructions: | I18: https://www.irs.gov/downloads/irs-pdf
B20: 4. | C20: It is vitally important to the continued success of this spreadsheet that users promptly report errors
C21: so that the spreadsheet can be corrected. | H21: Please report errors to: | I21: incometaxspreadsheet@gmail.com
B23: GENERAL NOTES:
B24: 1. | C24: Unprotected data entry cells have a light blue fill color.
C25: Cells containing calculated amounts are usually protected and have a darker blue fill color.
C26: Form and worksheet areas are protected. However, users are able to adjust printing properties.
C27: Formatting of cells, rows, and columns is also available.
B29: 2. | C29: "Manual override" cells are available for many calculated cells. The use of override cells is discouraged
C30: because manual overrides can defeat the spreadsheet's automatic updating feature. If you are having
C31: to use a manual override because of a spreadsheet error, be sure to report the error as soon as possible.
C33: NOTE: To clear data from an override cell, highlight it and then press the <Delete> key.
C34: Do not press the <space> bar because, although it is invisible, the <space> character is treated the
C35: same as any visible character.
B37: 3. | C37: To check a checkbox, simply type an 'X' (any character will work) in the box and press <Enter>.
C39: NOTE: To clear an 'X' from an checkbox, highlight it and then press the <Delete> key.
C40: Do not press the <space> bar because, although it is invisible, the <space> character is treated the
C41: same as any visible character.
B43: 4. | C43: Prior to printing, to remove colors from all forms and worksheets, place an 'X' in Cell AV2 on the '1040' sheet.
C44: Likewise, to remove social security numbers from all forms and worksheets, place an "X" in Cell AV3
C45: on the '1040' sheet.
B47: 5. | C47: If using copy/paste to copy information from another source, be sure to paste using 'Paste-Values'.
C48: Otherwise, cell properties could be inadvertently changed. (e.g. A normally unprotected cell could become
C49: protected.)
B51: 6. | C51: On Form 1040, to save time, it's generally okay to enter alternate information (e.g. SSN = 111-22-3333).
C52: Be aware, to perform an accurate tax calculation, the spreadsheet will need reasonably complete and
C53: accurate birthdate, accurate state of residence, and a valid SSN. Don't leave these cells blank.
...

Sheet W-2s
C1: Information from Form W-2, Wage and Tax Statement | G1: Maximum SS Tax Earnings: | H1: 176100 | I1: SS Tax Rate: | J1: 0.062 | L1: Max. SS Tax: | M1: =ROUND(MaxSSTaxEarnings*SSTaxRate,2) | N1: per person | P1: Notes
A2: Line | B2: Code | C2: =IF(Name_1st_Yours="","Enter your name on the"&CHAR(10)&"sheet labeled '1040'",NameYours) | D2: Your Employer #1 | E2: Your Employer #2 | F2: Your Employer #3 | G2: Your Employer #4 | H2: Your Employer #5 | I2: Your Employer #6 | J2: Total | K2: Excess | M2: Used at: | P2: Date
A3: 1 | C3: Wages, tips, other compensation | J3: =SUM(ROUND(D3,0),ROUND(E3,0),ROUND(F3,0),ROUND(G3,0),ROUND(H3,0),ROUND(I3,0)) | O3: 120000
A4: 2 | C4: Federal income tax withheld | J4: =SUM(ROUND(D4,0),ROUND(E4,0),ROUND(F4,0),ROUND(G4,0),ROUND(H4,0),ROUND(I4,0)) | O4: =0.19*O3
A5: 3 | C5: Social security wages | J5: =SUM(ROUND(D5,0),ROUND(E5,0),ROUND(F5,0),ROUND(G5,0),ROUND(H5,0),ROUND(I5,0)) | M5: Sch. SE, Line 8a, Form 8919, line 8 | O5: =IF(O3="",0,MIN(O3,MaxSSTaxEarnings))
A6: 4 | C6: Social security tax withheld | J6: =SUM(D6:I6) | K6: =IF(SUM(J6,-MaxSSTax)>0,SUM(J6,-MaxSSTax),0) | M6: =IF(AND(EmployerCountYou>1,K6>0),"Schedule 3, line 11.",IF(AND(EmployerCountYou=1,K6>0),"See note below.","")) | N6: =IF(K6<1000,TEXT(K6,"$0.00"),TEXT(K6,"$0,000.00")) | O6: =MIN(SSTaxRate*O3,MaxSSTax)
A7: 5 | C7: Medicare wages and tips | J7: =SUM(ROUND(D7,0),ROUND(E7,0),ROUND(F7,0),ROUND(G7,0),ROUND(H7,0),ROUND(I7,0)) | O7: =O3
A8: 6 | C8: Medicare tax withheld | J8: =SUM(ROUND(D8,0),ROUND(E8,0),ROUND(F8,0),ROUND(G8,0),ROUND(H8,0),ROUND(I8,0)) | M8: Only bolded amounts are used in this spreadsheet. | O8: =MedicareTaxRate*O7
A9: 7 | C9: Social Security Tips | J9: =SUM(ROUND(D9,0),ROUND(E9,0),ROUND(F9,0),ROUND(G9,0),ROUND(H9,0),ROUND(I9,0)) | M9: Sch. SE, Line 8a, Form 8919, line 8 | O9: 26789
A10: 8 | C10: Allocated Tips | J10: =SUM(ROUND(D10,0),ROUND(E10,0),ROUND(F10,0),ROUND(G10,0),ROUND(H10,0),ROUND(I10,0))
A11: 10 | C11: Dependent Care Benefits | J11: =SUM(ROUND(D11,0),ROUND(E11,0),ROUND(F11,0),ROUND(G11,0),ROUND(H11,0),ROUND(I11,0))
A12: 11 | C12: Nonqualified plans | J12: =SUM(ROUND(D12,0),ROUND(E12,0),ROUND(F12,0),ROUND(G12,0),ROUND(H12,0),ROUND(I12,0))
A13: 12 | B13: A | C13: Uncollected Social Security Tax on Tips | I13: --- | J13: =SUM(ROUND(D13,0),ROUND(E13,0),ROUND(F13,0),ROUND(G13,0),ROUND(H13,0)) | M13: Form 8919 (You), lines 1-5
A14: 12 | B14: B | C14: Uncollected Medicare tax on Tips | I14: --- | J14: =SUM(ROUND(D14,0),ROUND(E14,0),ROUND(F14,0),ROUND(G14,0),ROUND(H14,0)) | M14: Form 8919 (You), lines 1-5
A15: 12 | B15: H | C15: Elective Deferral to 501(c)(18)(D) plan | J15: =SUM(ROUND(D15,0),ROUND(E15,0),ROUND(F15,0),ROUND(G15,0),ROUND(H15,0),ROUND(I15,0)) | M15: Form 8880, line 2 (a)
A16: 12 | B16: K | C16: 20% Excise Tax on Excess 'golden parachute' payments | J16: =SUM(ROUND(D16,0),ROUND(E16,0),ROUND(F16,0),ROUND(G16,0),ROUND(H16,0),ROUND(I16,0)) | M16: Form 1040, Sch. 2, line 17k
A17: 12 | B17: M | C17: Uncollected Social Security tax on group-term life (former employees) | J17: =SUM(ROUND(D17,0),ROUND(E17,0),ROUND(F17,0),ROUND(G17,0),ROUND(H17,0),ROUND(I17,0)) | M17: Form 1040, Sch. 2, line 13
A18: 12 | B18: N | C18: Uncollected medicare tax on group-term life (former employees) | J18: =SUM(ROUND(D18,0),ROUND(E18,0),ROUND(F18,0),ROUND(G18,0),ROUND(H18,0),ROUND(I18,0)) | M18: Form 1040, Sch. 2, line 13
A19: 12 | B19: P | C19: Excludable moving expense reinbursements for military | J19: =SUM(ROUND(D19,0),ROUND(E19,0),ROUND(F19,0),ROUND(G19,0),ROUND(H19,0),ROUND(I19,0)) | M19: Form 1040, Sch. 2, line 14
A20: 12 | B20: Q | C20: Non Taxable Combat Pay | J20: =SUM(ROUND(D20,0),ROUND(E20,0),ROUND(F20,0),ROUND(G20,0),ROUND(H20,0),ROUND(I20,0)) | M20: Form 2441, Part 4 of Earned Income Worksheet for Line 4
A21: 12 | B21: S | C21: Elective deferral to SIMPLE IRA | J21: =SUM(ROUND(D21,0),ROUND(E21,0),ROUND(F21,0),ROUND(G21,0),ROUND(H21,0),ROUND(I21,0)) | M21: Form 8880, line 2 (a)
A22: 12 | B22: W | C22: Employer contributions to HSA. | J22: =SUM(ROUND(D22,0),ROUND(E22,0),ROUND(F22,0),ROUND(G22,0),ROUND(H22,0),ROUND(I22,0)) | M22: Form 8889, Part I, line 9 (You)
A23: 13 | C23: Stat Emp / Retire / 3rd Party Sick | J23: =SUM(ROUND(D23,0),ROUND(E23,0),ROUND(F23,0),ROUND(G23,0),ROUND(H23,0),ROUND(I23,0))
A24: 14 | C24: Other | J24: =SUM(ROUND(D24,0),ROUND(E24,0),ROUND(F24,0),ROUND(G24,0),ROUND(H24,0),ROUND(I24,0))
A25: 14 | C25: Railroad retire (RRTA) compensation | J25: =SUM(ROUND(D25,0),ROUND(E25,0),ROUND(F25,0),ROUND(G25,0),ROUND(H25,0),ROUND(I25,0)) | M25: =IF(J35,"Form 8959, line 14","")
A26: 14 | C26: RRTA medicare tax withheld (see Form CT-2) | J26: =SUM(ROUND(D26,0),ROUND(E26,0),ROUND(F26,0),ROUND(G26,0),ROUND(H26,0),ROUND(I26,0))
A27: 15 | C27: State - Employer's state ID number | J27: - - -
A28: 16 | C28: State wages, tips, etc. | J28: =SUM(ROUND(D28,0),ROUND(E28,0),ROUND(F28,0),ROUND(G28,0),ROUND(H28,0),ROUND(I28,0))
A29: 17 | C29: State income tax | J29: =SUM(ROUND(D29,0),ROUND(E29,0),ROUND(F29,0),ROUND(G29,0),ROUND(H29,0),ROUND(I29,0)) | O29: =0.05*O3
A30: 18 | C30: Local wages, tips, etc. | J30: =SUM(ROUND(D30,0),ROUND(E30,0),ROUND(F30,0),ROUND(G30,0),ROUND(H30,0),ROUND(I30,0))
A31: 19 | C31: Local income tax | J31: =SUM(ROUND(D31,0),ROUND(E31,0),ROUND(F31,0),ROUND(G31,0),ROUND(H31,0),ROUND(I31,0))
A32: 20 | C32: Locality name | J32: - - -
C33: Employer count (You) | D33: =IF(D6<>"",1,0) | E33: =IF(E6<>"",1,0) | F33: =IF(F6<>"",1,0) | G33: =IF(G6<>"",1,0) | H33: =IF(H6<>"",1,0) | I33: =IF(I6<>"",1,0) | J33: =SUM(D33:I33)
C34: ="Medicare wages and tip > "&TEXT(K34,"$0,000") | D34: =(D7>$K34) | E34: =(E7>$K34) | F34: =(F7>$K34) | G34: =(G7>$K34) | H34: =(H7>$K34) | I34: =(I7>$K34) | J34: =OR(D34:I34) | K34: ='8959'!$H$24
C35: ="RRTA > "&TEXT(K35,"$0,000") | D35: =IF(D25>'8959'!$H$24,TRUE,FALSE) | E35: =IF(E25>'8959'!$H$24,TRUE,FALSE) | F35: =IF(F25>'8959'!$H$24,TRUE,FALSE) | G35: =IF(G25>'8959'!$H$24,TRUE,FALSE) | H35: =IF(H25>'8959'!$H$24,TRUE,FALSE) | I35: =IF(I25>'8959'!$H$24,TRUE,FALSE) | J35: =OR(D35:I35) | K35: ='8959'!H46
D36: =IF(AND(J6>MaxSSTax,EmployerCountYou=1),"Notify your employer that they withheld "&N6&" too much Social Security Tax or file Form 843, Claim for Refund and Request for Abatement.","")
C37: =IF(OR(AND(D7="",D8<>""),AND(E7="",E8<>""),AND(F7="",F8<>""),AND(G7="",G8<>"")),"CAUTION: Entering an amount into Line 6 without entering an amount into Line 5 will result in a tax calculation error.","")
C38: Information from Form W-2, Wage and Tax Statement
A39: Line | B39: Code | C39: =IF(Name_1st_Sp="","Enter your spouse's name on"&CHAR(10)&"the sheet labeled '1040'",NameSpouse) | D39: Spouse's Employer #1 | E39: Spouse's Employer #2 | F39: Spouse's Employer #3 | G39: Spouse's Employer #4 | H39: Spouse's Employer #5 | I39: Spouse's Employer #6 | J39: Total | K39: Excess | M39: Used at: | O39: 0.75
A40: 1 | C40: Wages, tips, other compensation | J40: =SUM(ROUND(D40,0),ROUND(E40,0),ROUND(F40,0),ROUND(G40,0),ROUND(H40,0),ROUND(I40,0)) | O40: =O3*$O$39
...

Sheet 1099-INT
B1: Information from Form 1099-INT, Interest Income | K1: Notes
C2: =IF(Name_1st_Yours="","Enter your name(s) on the"&CHAR(10)&"sheet lableled '1040'",IF(File_Marr_Joint<>"",NameYours&CHAR(10)&" and "&NameSpouse,NameYours)) | D2: Payer #1 | E2: Payer #2 | F2: Payer #3 | G2: Payer #4 | H2: Payer #5 | K2: Date:
C3: PAYER's name
C4: PAYER's Federal ID number
C5: Account number
B6: 1 | C6: Interest income | AA6: =ROUND(D6,0) | AB6: =ROUND(E6,0) | AC6: =ROUND(F6,0) | AD6: =ROUND(G6,0) | AE6: =ROUND(H6,0)
B7: 2 | C7: Early withdrawal penalty | AA7: =ROUND(D7,0) | AB7: =ROUND(E7,0) | AC7: =ROUND(F7,0) | AD7: =ROUND(G7,0) | AE7: =ROUND(H7,0)
B8: 3 | C8: Interest on U.S. Savings Bonds & Treas. Obligations | AA8: =ROUND(D8,0) | AB8: =ROUND(E8,0) | AC8: =ROUND(F8,0) | AD8: =ROUND(G8,0) | AE8: =ROUND(H8,0)
B9: 3A | C9: Include Line 3 on Schedule B, Line 1? (Y / N) | D9: N | E9: N | F9: N | G9: N | H9: N
B10: 4 | C10: Federal income tax withheld | AA10: =ROUND(D10,0) | AB10: =ROUND(E10,0) | AC10: =ROUND(F10,0) | AD10: =ROUND(G10,0) | AE10: =ROUND(H10,0)
B11: 5 | C11: Investment expenses | AA11: =ROUND(D11,0) | AB11: =ROUND(E11,0) | AC11: =ROUND(F11,0) | AD11: =ROUND(G11,0) | AE11: =ROUND(H11,0)
B12: 6 | C12: Foreign tax paid | I12: =IF(SUM(D12:H12)>0,"Check Form 1116, Foreign Tax Credit","") | AA12: =ROUND(D12,0) | AB12: =ROUND(E12,0) | AC12: =ROUND(F12,0) | AD12: =ROUND(G12,0) | AE12: =ROUND(H12,0)
B13: 7 | C13: Foreign country or U.S. possession | AA13: =ROUND(D13,0) | AB13: =ROUND(E13,0) | AC13: =ROUND(F13,0) | AD13: =ROUND(G13,0) | AE13: =ROUND(H13,0)
B14: 8 | C14: Tax-exempt interest | AA14: =ROUND(D14,0) | AB14: =ROUND(E14,0) | AC14: =ROUND(F14,0) | AD14: =ROUND(G14,0) | AE14: =ROUND(H14,0)
B15: 9 | C15: Specified private activity bond interest | AA15: =ROUND(D15,0) | AB15: =ROUND(E15,0) | AC15: =ROUND(F15,0) | AD15: =ROUND(G15,0) | AE15: =ROUND(H15,0)
B17: 10 | C17: Market discount | AA17: =ROUND(D17,0) | AB17: =ROUND(E17,0) | AC17: =ROUND(F17,0) | AD17: =ROUND(G17,0) | AE17: =ROUND(H17,0)
B18: 11 | C18: Bond premium | AA18: =ROUND(D18,0) | AB18: =ROUND(E18,0) | AC18: =ROUND(F18,0) | AD18: =ROUND(G18,0) | AE18: =ROUND(H18,0)
B19: 12 | C19: Bond premium on Treasury obligations | AA19: =ROUND(D19,0) | AB19: =ROUND(E19,0) | AC19: =ROUND(F19,0) | AD19: =ROUND(G19,0) | AE19: =ROUND(H19,0)
B20: 13 | C20: Bond premium on tax–exempt bond | AA20: =ROUND(D20,0) | AB20: =ROUND(E20,0) | AC20: =ROUND(F20,0) | AD20: =ROUND(G20,0) | AE20: =ROUND(H20,0)
B21: 14 | C21: Tax-exempt and tax credit bond CUSIP no. | AA21: =ROUND(D21,0) | AB21: =ROUND(E21,0) | AC21: =ROUND(F21,0) | AD21: =ROUND(G21,0) | AE21: =ROUND(H21,0)
B22: 15 | C22: State
B23: 16 | C23: State identification no.
B24: 17 | C24: State tax withheld | AA24: =ROUND(D24,0) | AB24: =ROUND(E24,0) | AC24: =ROUND(F24,0) | AD24: =ROUND(G24,0) | AE24: =ROUND(H24,0)
B25: Only bolded amounts are used in this spreadsheet.
D26: =IF(OR(LEFT(D9,1)="Y",LEFT(D9,1)="y"),D8,"") | E26: =IF(OR(LEFT(E9,1)="Y",LEFT(E9,1)="y"),E8,"") | F26: =IF(OR(LEFT(F9,1)="Y",LEFT(F9,1)="y"),F8,"") | G26: =IF(OR(LEFT(G9,1)="Y",LEFT(G9,1)="y"),G8,"") | H26: =IF(OR(LEFT(H9,1)="Y",LEFT(H9,1)="y"),H8,"")
D27: =IF(D3<>"",D3,"") | E27: =IF(E3<>"",E3,"") | F27: =IF(F3<>"",F3,"") | G27: =IF(G3<>"",G3,"") | H27: =IF(H3<>"",H3,"")
D28: =IF(D4<>"", " - "&D4,"") | E28: =IF(E4<>"", " - "&E4,"") | F28: =IF(F4<>"", " - "&F4,"") | G28: =IF(G4<>"", " - "&G4,"") | H28: =IF(H4<>"", " - "&H4,"")
D29: =IF(D5<>""," - "&D5,"") | E29: =IF(E5<>""," - "&E5,"") | F29: =IF(F5<>""," - "&F5,"") | G29: =IF(G5<>""," - "&G5,"") | H29: =IF(H5<>""," - "&H5,"")
D30: =D27&D28&D29 | E30: =E27&E28&E29 | F30: =F27&F28&F29 | G30: =G27&G28&G29 | H30: =H27&H28&H29
C31: =IF(Name_1st_Yours="","Enter your name(s) on the"&CHAR(10)&"sheet lableled '1040'",IF(File_Marr_Joint<>"",NameYours&CHAR(10)&" and "&NameSpouse,NameYours)) | D31: Payer #6 | E31: Payer #7 | F31: Payer #8 | G31: Payer #9 | H31: Payer #10
C32: PAYER's name
C33: PAYER's Federal ID number
C34: Account number
B35: 1 | C35: Interest income | AA35: =ROUND(D35,0) | AB35: =ROUND(E35,0) | AC35: =ROUND(F35,0) | AD35: =ROUND(G35,0) | AE35: =ROUND(H35,0)
B36: 2 | C36: Early withdrawal penalty | AA36: =ROUND(D36,0) | AB36: =ROUND(E36,0) | AC36: =ROUND(F36,0) | AD36: =ROUND(G36,0) | AE36: =ROUND(H36,0)
B37: 3 | C37: Interest on U.S. Savings Bonds & Treas. Obligations | AA37: =ROUND(D37,0) | AB37: =ROUND(E37,0) | AC37: =ROUND(F37,0) | AD37: =ROUND(G37,0) | AE37: =ROUND(H37,0)
B38: 3A | C38: Include Line 3 on Schedule B, Line 1? (Y / N) | D38: N | E38: N | F38: N | G38: N | H38: N
B39: 4 | C39: Federal income tax withheld | AA39: =ROUND(D39,0) | AB39: =ROUND(E39,0) | AC39: =ROUND(F39,0) | AD39: =ROUND(G39,0) | AE39: =ROUND(H39,0)
B40: 5 | C40: Investment expenses | AA40: =ROUND(D40,0) | AB40: =ROUND(E40,0) | AC40: =ROUND(F40,0) | AD40: =ROUND(G40,0) | AE40: =ROUND(H40,0)
B41: 6 | C41: Foreign tax paid | I41: =IF(SUM(D41:H41)>0,"Check Form 1116, Foreign Tax Credit","") | AA41: =ROUND(D41,0) | AB41: =ROUND(E41,0) | AC41: =ROUND(F41,0) | AD41: =ROUND(G41,0) | AE41: =ROUND(H41,0)
...

Sheet 1099-DIV
B1: Information from Form 1099-DIV, Dividends and Distributions | K1: Notes
C2: =IF(Name_1st_Yours="","Enter your name(s) on the"&CHAR(10)&"sheet labeled '1040'",Names) | D2: Payer #1 | E2: Payer #2 | F2: Payer #3 | G2: Payer #4 | H2: Payer #5 | K2: Date:
C3: PAYER's name
C4: PAYER's Federal ID number
C5: Account number
B6: 1a | C6: Total ordinary dividends | I6: =IF(I26,"Error: All qualified dividends must be included in","") | AA6: =B6 | AB6: =ROUND(D6,2) | AC6: =ROUND(E6,2) | AD6: =ROUND(F6,2) | AE6: =ROUND(G6,2) | AF6: =ROUND(H6,2)
B7: 1b | C7: Qualified dividends | I7: =IF(I26,"the Total ordinary dividend amount.","") | AA7: =B7 | AB7: =ROUND(D7,2) | AC7: =ROUND(E7,2) | AD7: =ROUND(F7,2) | AE7: =ROUND(G7,2) | AF7: =ROUND(H7,2)
B8: 2a | C8: Total capital gain distr. | AA8: =B8 | AB8: =ROUND(D8,0) | AC8: =ROUND(E8,0) | AD8: =ROUND(F8,0) | AE8: =ROUND(G8,0) | AF8: =ROUND(H8,0)
B9: 2b | C9: Unrecap. Sec. 1250 gain | AA9: =B9 | AB9: =ROUND(D9,0) | AC9: =ROUND(E9,0) | AD9: =ROUND(F9,0) | AE9: =ROUND(G9,0) | AF9: =ROUND(H9,0)
B10: 2c | C10: Section 1202 gain | AA10: =B10 | AB10: =ROUND(D10,2) | AC10: =ROUND(E10,2) | AD10: =ROUND(F10,2) | AE10: =ROUND(G10,2) | AF10: =ROUND(H10,2)
B11: 2d | C11: Collectibles (28%) gain | AA11: =B11 | AB11: =ROUND(D11,2) | AC11: =ROUND(E11,2) | AD11: =ROUND(F11,2) | AE11: =ROUND(G11,2) | AF11: =ROUND(H11,2)
B12: 3 | C12: Nondividend distributions | AA12: =B12 | AB12: =ROUND(D12,0) | AC12: =ROUND(E12,0) | AD12: =ROUND(F12,0) | AE12: =ROUND(G12,0) | AF12: =ROUND(H12,0)
B13: 4 | C13: Federal income tax withheld | AA13: =B13 | AB13: =ROUND(D13,2) | AC13: =ROUND(E13,2) | AD13: =ROUND(F13,2) | AE13: =ROUND(G13,2) | AF13: =ROUND(H13,2)
B14: 5 | C14: Section 199A dividends | AA14: =B14 | AB14: =ROUND(D14,2) | AC14: =ROUND(E14,2) | AD14: =ROUND(F14,2) | AE14: =ROUND(G14,2) | AF14: =ROUND(H14,2)
B15: 6 | C15: Investment expenses | AA15: =B15 | AB15: =ROUND(D15,0) | AC15: =ROUND(E15,0) | AD15: =ROUND(F15,0) | AE15: =ROUND(G15,0) | AF15: =ROUND(H15,0)
B16: 7 | C16: Foreign tax paid | I16: =IF(SUM(D16:H16)>0,"Check Form 1116, Foreign Tax Credit","") | AA16: =B16 | AB16: =ROUND(D16,2) | AC16: =ROUND(E16,2) | AD16: =ROUND(F16,2) | AE16: =ROUND(G16,2) | AF16: =ROUND(H16,2)
B17: 8 | C17: Foreign country or U.S. possession | AA17: =B17
B18: 9 | C18: Cash liquidation distributions | AA18: =B18 | AB18: =ROUND(D18,0) | AC18: =ROUND(E18,0) | AD18: =ROUND(F18,0) | AE18: =ROUND(G18,0) | AF18: =ROUND(H18,0)
B19: 10 | C19: Noncash liquidation distributions | AA19: =B19 | AB19: =ROUND(D19,0) | AC19: =ROUND(E19,0) | AD19: =ROUND(F19,0) | AE19: =ROUND(G19,0) | AF19: =ROUND(H19,0)
B20: 11 | C20: FATCA filing requirement | AA20: =B20 | AB20: =ROUND(D20,2) | AC20: =ROUND(E20,2) | AD20: =ROUND(F20,2) | AE20: =ROUND(G20,2) | AF20: =ROUND(H20,2)
B21: 12 | C21: Exempt-interest dividends | AA21: =B21 | AB21: =ROUND(D21,2) | AC21: =ROUND(E21,2) | AD21: =ROUND(F21,2) | AE21: =ROUND(G21,2) | AF21: =ROUND(H21,2)
B22: 13 | C22: Specified private activity bond interest dividends | AA22: =B22 | AB22: =ROUND(D22,2) | AC22: =ROUND(E22,2) | AD22: =ROUND(F22,2) | AE22: =ROUND(G22,2) | AF22: =ROUND(H22,2)
B23: 14 | C23: State | AA23: =B23
B24: 15 | C24: State identification no. | AA24: =B24
B25: 16 | C25: State tax withheld | AA25: =B25 | AB25: =ROUND(D25,2) | AC25: =ROUND(E25,2) | AD25: =ROUND(F25,2) | AE25: =ROUND(G25,2) | AF25: =ROUND(H25,2)
B26: Only bolded amounts are used in this spreadsheet. | D26: =D7>D6 | E26: =E7>E6 | F26: =F7>F6 | G26: =G7>G6 | H26: =H7>H6 | I26: =OR(D26:H26)
D27: =IF(D3<>"",D3,"") | E27: =IF(E3<>"",E3,"") | F27: =IF(F3<>"",F3,"") | G27: =IF(G3<>"",G3,"") | H27: =IF(H3<>"",H3,"")
D28: =IF(D4<>"", " - "&D4,"") | E28: =IF(E4<>"", " - "&E4,"") | F28: =IF(F4<>"", " - "&F4,"") | G28: =IF(G4<>"", " - "&G4,"") | H28: =IF(H4<>"", " - "&H4,"")
D29: =IF(D5<>""," - "&D5,"") | E29: =IF(E5<>""," - "&E5,"") | F29: =IF(F5<>""," - "&F5,"") | G29: =IF(G5<>""," - "&G5,"") | H29: =IF(H5<>""," - "&H5,"")
D30: =IF(D6="","",D27&D28&D29) | E30: =IF(E6="","",E27&E28&E29) | F30: =IF(F6="","",F27&F28&F29) | G30: =IF(G6="","",G27&G28&G29) | H30: =IF(H6="","",H27&H28&H29)
C31: =IF(Name_1st_Yours="","Enter your name(s) on the"&CHAR(10)&"sheet labeled '1040'",Names) | D31: Payer #6 | E31: Payer #7 | F31: Payer #8 | G31: Payer #9 | H31: Payer #10
C32: PAYER's name
C33: PAYER's Federal ID number
C34: Account number
B35: 1a | C35: Total ordinary dividends | I35: =IF(I55,"Error: All qualified dividends must be included in","") | AA35: =B35 | AB35: =ROUND(D35,2) | AC35: =ROUND(E35,2) | AD35: =ROUND(F35,2) | AE35: =ROUND(G35,2) | AF35: =ROUND(H35,2)
B36: 1b | C36: Qualified dividends | I36: =IF(I55,"the Total ordinary dividend amount.","") | AA36: =B36 | AB36: =ROUND(D36,2) | AC36: =ROUND(E36,2) | AD36: =ROUND(F36,2) | AE36: =ROUND(G36,2) | AF36: =ROUND(H36,2)
B37: 2a | C37: Total capital gain distr. | AA37: =B37 | AB37: =ROUND(D37,0) | AC37: =ROUND(E37,0) | AD37: =ROUND(F37,0) | AE37: =ROUND(G37,0) | AF37: =ROUND(H37,0)
B38: 2b | C38: Unrecap. Sec. 1250 gain | AA38: =B38 | AB38: =ROUND(D38,0) | AC38: =ROUND(E38,0) | AD38: =ROUND(F38,0) | AE38: =ROUND(G38,0) | AF38: =ROUND(H38,0)
B39: 2c | C39: Section 1202 gain | AA39: =B39 | AB39: =ROUND(D39,2) | AC39: =ROUND(E39,2) | AD39: =ROUND(F39,2) | AE39: =ROUND(G39,2) | AF39: =ROUND(H39,2)
B40: 2d | C40: Collectibles (28%) gain | AA40: =B40 | AB40: =ROUND(D40,2) | AC40: =ROUND(E40,2) | AD40: =ROUND(F40,2) | AE40: =ROUND(G40,2) | AF40: =ROUND(H40,2)
...

Sheet 1099-G
B1: Form 1099-G, Certain Government Payments | E1: =IF(FALSE,"After Form 1040 and Schedule 1 are complete,"&CHAR(10)&" be sure to review 'Sch. 1 Line 8 WS', line 1.",IF(FALSE,"'Sch. 1 Line 8 WS', line 1, has been Updated.","")) | M1: Notes
C2: =IF(Name_1st_Yours="","Enter your name on the"&CHAR(10)&"sheet labeled '1040'",NameYours) | D2: Payer #1 | E2: Payer #2 | F2: Payer #3 | G2: Payer #4 | H2: Payer #5 | I2: Payer #6 | J2: Your Total | K2: Used at:
C3: PAYER's name
C4: PAYER's TIN
C5: Account number
B6: 1 | C6: Unemployment Compensation | J6: =ROUND(SUM(D6:I6),0) | K6: Sch. 1 Line 8 WS', line 7
B7: 2 | C7: State or local income tax refunds, credits, offsets | J7: =ROUND(SUM(D7:I7),0) | K7: =IF(Needs_SALT," See sheet labeled"," 'Sch. 1, Line 1 (SALT)', line 1 [State & local tax]")
B8: 3 | C8: Box 2 amount is for tax year | J8: --- | K8: =IF(Needs_SALT,"'Sch. 1, Line 1 (SALT)'. (State & Local Tax)","")
B9: 4 | C9: Federal income tax withheld | J9: =ROUND(SUM(D9:I9),0)
B10: 5 | C10: RTAA Payments | J10: =ROUND(SUM(D10:I10),0)
B11: 6 | C11: Taxable grants | J11: =ROUND(SUM(D11:I11),0)
B12: 7a | C12: Agriculture payments - Disaster payments | J12: =ROUND(SUM(D12:I12),0)
B13: 7b | C13: Agriculture payments - Other payments | J13: =ROUND(SUM(D13:I13),0) | K13: =AND(D13="",E13="",F13="",G13="",J13="")
B14: 8 | C14: Check if box 2 is trade or business income
B15: 9 | C15: Market gain | J15: =ROUND(SUM(D15:I15),0) | K15: =AND(D15="",E15="",F15="",G15="",J15="")
B16: 10a | C16: State
B17: 10b | C17: State identification no.
B18: 11 | C18: State income tax withheld | J18: =ROUND(SUM(D18:I18),0)
B19: Only bolded amounts are used in this spreadsheet.
J20: =IF(J3<>"",J3,"")
C21: =IF(Name_1st_Sp="","Enter your spouse's name on"&CHAR(10)&"the sheet labeled '1040'",NameSpouse) | D21: Payer #1 | E21: Payer #2 | F21: Payer #3 | G21: Payer #4 | H21: Payer #5 | I21: Spouse Total | J21: Total | K21: Used at:
C22: PAYER's name
C23: PAYER's Federal ID number
C24: Account number | K24: =SUM(ForeignTaxPaid_INT,ForeignTaxPaid_DIV)
B25: 1 | C25: Unemployment Compensation | I25: =ROUND(SUM(D25:G25),0) | J25: =SUM(UCE_You,UCE_Spouse) | K25: Sch. 1 Line 8 WS', line 8 / Sch. 1, line 7
B26: 2 | C26: State or local income tax refunds, credits, offsets | I26: =ROUND(SUM(D26:G26),0) | J26: =SUM(J7,I26) | K26: =IF(Needs_SALT," See sheet labeled"," 'Sch. 1, Line 1 (SALT)', line 1 [State & local tax]")
B27: 3 | C27: Box 2 amount is for tax year | I27: --- | J27: --- | K27: =IF(Needs_SALT," 'Sch. 1, Line 1 (SALT)'. (State & Local Tax)","")
B28: 4 | C28: Federal income tax withheld | I28: =ROUND(SUM(D28:G28),0) | J28: =SUM(J9,I28) | K28: 1040, line 25b
B29: 5 | C29: RTAA Payments | I29: =ROUND(SUM(D29:G29),0) | J29: =SUM(J10,I29) | K29: Sch. 1, line 8z
B30: 6 | C30: Taxable grants | I30: =ROUND(SUM(D30:G30),0) | J30: =SUM(J11,I30) | K30: Sch. 1, line 8z
B31: 7a | C31: Agriculture payments - Disaster payments | I31: =ROUND(SUM(D31:G31),0) | J31: =SUM(J12,I31) | K31: Sch. F, Line 6a
B32: 7b | C32: Agriculture payments - Other payments | I32: =ROUND(SUM(D32:G32),0) | J32: =SUM(J13,I32) | K32: Sch. F, Line 4a
B33: 8 | C33: Check if box 2 is trade or business income | K33: =AND(K13,D31="",E31="",F31="",G31="")
B34: 9 | C34: Market gain | I34: =ROUND(SUM(D34:G34),0) | J34: =SUM(J15,I34) | K34: Sch. F, Line 4a
B35: 10a | C35: State | K35: =AND(K15,D33="",E33="",F33="",G33="")
B36: 10b | C36: State identification no.
B37: 11 | C37: State income tax withheld | I37: =ROUND(SUM(D37:G37),0) | J37: =SUM(J18,I37) | K37: Sch. A, Line 5a
B38: Only bolded amounts are used in this spreadsheet.
C43: Table of Contents

Sheet 1099-MISC
C3: This form has yet to be implemented.
C5: Download and follow IRS instructions for where the information and amounts should be entered.
C7: NOTE: | D7: Amounts of more than $600 will NOT typically be reported on Schedule 1 (Form 1040), Line 8 a - z.
C9: Form 1099-MISC and Instructions may be downloaded from the IRS:"
C10: https://www.irs.gov/pub/irs-pdf/f1099msc.pdf | H10: https://www.irs.gov/instructions/i1099mec
C70: Table of Contents

Sheet 1099-NEC
B1: Form 1099-NEC, Nonemployee Compensation | E1: =IF(FALSE,"After Form 1040 and Schedule 1 are complete,"&CHAR(10)&" be sure to review 'Sch. 1 Line 8 WS', line 1.",IF(FALSE,"'Sch. 1 Line 8 WS', line 1, has been Updated.","")) | M1: Notes
C2: =IF(Name_1st_Yours="","Enter your name on the"&CHAR(10)&"sheet labeled '1040'",NameYours) | D2: Payer #1 | E2: Payer #2 | F2: Payer #3 | G2: Payer #4 | H2: Payer #5 | I2: Payer #6 | J2: Your Total | K2: Used at:
C3: PAYER's name | J3: ---
C4: PAYER's TIN | J4: ---
C5: Account number | J5: ---
B6: 1 | C6: Nonemployee compensation | J6: =ROUND(SUM(D6:I6),0) | K6: Sch C, line 1 (for you)
B7: 2 | C7: Payer made direct sales of $5,000 or more of consumer productes to recipient for resale | D7: Y/ N | E7: Y/ N | F7: Y/ N | G7: Y/ N | H7: Y/ N | I7: Y/ N | J7: ---
B8: 3 | C8: Excess golden parachute payments | J8: =ROUND(SUM(D8:I8),0) | K8: =IF(Needs_SALT,"'Sch. 1, Line 1 (SALT)'. (State & Local Tax)","")
B9: 4 | C9: Federal income tax withheld | J9: =ROUND(SUM(D9:I9),0)
B10: 5 | C10: State tax withheld | J10: =ROUND(SUM(D10:I10),0)
B11: 6 | C11: State/Payer's state no. | J11: =ROUND(SUM(D11:I11),0)
B12: 7 | C12: State income | J12: =ROUND(SUM(D12:I12),0)
B13: Only bolded amounts are used in this spreadsheet.
J14: =IF(J3<>"",J3,"")
C15: =IF(Name_1st_Sp="","Enter your spouse's name on"&CHAR(10)&"the sheet labeled '1040'",NameSpouse) | D15: Payer #1 | E15: Payer #2 | F15: Payer #3 | G15: Payer #4 | H15: Payer #5 | I15: Spouse Total | J15: Total | K15: Used at:
C16: PAYER's name | J16: ---
C17: PAYER's Federal ID number | J17: ---
C18: Account number | J18: --- | K18: =SUM(ForeignTaxPaid_INT,ForeignTaxPaid_DIV)
B19: 1 | C19: Nonemployee compensation | I19: =ROUND(SUM(D19:H19),0) | J19: =SUM(NonEmployeeComp_You,NonEmployeeComp_Spouse) | K19: Sch C, line 1 (for your spouse)
B20: 2 | C20: Payer made direct sales of $5,000 or more of consumer productes to recipient for resale | D20: Y/ N | E20: Y/ N | F20: Y/ N | G20: Y/ N | H20: Y/ N | I20: --- | J20: ---
B21: 3 | C21: Excess golden parachute payments | I21: =ROUND(SUM(D21:H21),0) | J21: =SUM(J8,I21)
B22: 4 | C22: Federal income tax withheld | I22: =ROUND(SUM(D22:H22),0) | J22: =SUM(J9,I22) | K22: Form 1040, line 25b
B23: 5 | C23: State tax withheld | I23: =ROUND(SUM(D23:H23),0) | J23: =SUM(J10,I23) | K23: Sch. A, line 5a
B24: 6 | C24: State/Payer's state no. | I24: =ROUND(SUM(D24:H24),0) | J24: =SUM(J11,I24)
B25: 7 | C25: State income | I25: =ROUND(SUM(D25:H25),0) | J25: =SUM(J12,I25)
B26: Only bolded amounts are used in this spreadsheet.
C31: Table of Contents

Sheet 1099-R
B1: Information from Form 1099-R, Distributions From Pensions, Annuities, Retirement or Profit-Sharing Plans, IRAs, Insurance Contracts, etc. | AU1: Notes
C2: =IF(Name_1st_Yours="","Enter your name on the"&CHAR(10)&"sheet labeled '1040'",NameYours) | D2: Enter payer's name here. | E2: Payer #2 | F2: Payer #3 | G2: Payer #4 | H2: Payer #5 | I2: Payer #6 | J2: Payer #7 | K2: Payer #8 | L2: Payer #9 | M2: Total IRAs | N2: Total Pension / Annuities | O2: Qualified CONVersion to ROTH IRA | U2: IRA | AE2: P/A | AO2: CONV
C3: Enter "IRA" or "P/A" or "CONV" >>> | M3: IRA | N3: P/A | O3: CONV | Q3: =NOT(AND(ISERROR(FIND("IRA",D3,1)),ISERROR(FIND("ira",D3,1)))) | R3: =NOT(AND(ISERROR(FIND("IRA",E3,1)),ISERROR(FIND("ira",E3,1)))) | S3: =NOT(AND(ISERROR(FIND("IRA",F3,1)),ISERROR(FIND("ira",F3,1)))) | T3: =NOT(AND(ISERROR(FIND("IRA",G3,1)),ISERROR(FIND("ira",G3,1)))) | U3: =NOT(AND(ISERROR(FIND("IRA",H3,1)),ISERROR(FIND("ira",H3,1)))) | V3: =NOT(AND(ISERROR(FIND("IRA",I3,1)),ISERROR(FIND("ira",I3,1)))) | W3: =NOT(AND(ISERROR(FIND("IRA",J3,1)),ISERROR(FIND("ira",J3,1)))) | X3: =NOT(AND(ISERROR(FIND("IRA",K3,1)),ISERROR(FIND("ira",K3,1)))) | Y3: =NOT(AND(ISERROR(FIND("IRA",L3,1)),ISERROR(FIND("ira",L3,1)))) | AA3: =NOT(AND(ISERROR(FIND("P/A",D3,1)),ISERROR(FIND("p/a",D3,1)))) | AB3: =NOT(AND(ISERROR(FIND("P/A",E3,1)),ISERROR(FIND("p/a",E3,1)))) | AC3: =NOT(AND(ISERROR(FIND("P/A",F3,1)),ISERROR(FIND("p/a",F3,1)))) | AD3: =NOT(AND(ISERROR(FIND("P/A",G3,1)),ISERROR(FIND("p/a",G3,1)))) | AE3: =NOT(AND(ISERROR(FIND("P/A",H3,1)),ISERROR(FIND("p/a",H3,1)))) | AF3: =NOT(AND(ISERROR(FIND("P/A",I3,1)),ISERROR(FIND("p/a",I3,1)))) | AG3: =NOT(AND(ISERROR(FIND("P/A",J3,1)),ISERROR(FIND("p/a",J3,1)))) | AH3: =NOT(AND(ISERROR(FIND("P/A",K3,1)),ISERROR(FIND("p/a",K3,1)))) | AI3: =NOT(AND(ISERROR(FIND("P/A",L3,1)),ISERROR(FIND("p/a",L3,1)))) | AK3: =NOT(AND(ISERROR(FIND("CONV",D3,1)),ISERROR(FIND("conv",D3,1)))) | AL3: =NOT(AND(ISERROR(FIND("CONV",E3,1)),ISERROR(FIND("conv",E3,1)))) | AM3: =NOT(AND(ISERROR(FIND("CONV",F3,1)),ISERROR(FIND("conv",F3,1)))) | AN3: =NOT(AND(ISERROR(FIND("CONV",G3,1)),ISERROR(FIND("conv",G3,1)))) | AO3: =NOT(AND(ISERROR(FIND("CONV",H3,1)),ISERROR(FIND("conv",H3,1)))) | AP3: =NOT(AND(ISERROR(FIND("CONV",I3,1)),ISERROR(FIND("conv",I3,1)))) | AQ3: =NOT(AND(ISERROR(FIND("CONV",J3,1)),ISERROR(FIND("conv",J3,1)))) | AR3: =NOT(AND(ISERROR(FIND("CONV",K3,1)),ISERROR(FIND("conv",K3,1)))) | AS3: =NOT(AND(ISERROR(FIND("CONV",L3,1)),ISERROR(FIND("conv",L3,1))))
B4: 1 | C4: Gross distribution | M4: =SUM(Q4:Y4) | N4: =SUM(AA4:AI4) | O4: =SUM(AK4:AS4) | Q4: =IF(Q$3,ROUND(D4,0),0) | R4: =IF(R$3,ROUND(E4,0),0) | S4: =IF(S$3,ROUND(F4,0),0) | T4: =IF(T$3,ROUND(G4,0),0) | U4: =IF(U$3,ROUND(H4,0),0) | V4: =IF(V$3,ROUND(I4,0),0) | W4: =IF(W$3,ROUND(J4,0),0) | X4: =IF(X$3,ROUND(K4,0),0) | Y4: =IF(Y$3,ROUND(L4,0),0) | AA4: =IF(AA$3,ROUND(D4,0),0) | AB4: =IF(AB$3,ROUND(E4,0),0) | AC4: =IF(AC$3,ROUND(F4,0),0) | AD4: =IF(AD$3,ROUND(G4,0),0) | AE4: =IF(AE$3,ROUND(H4,0),0) | AF4: =IF(AF$3,ROUND(I4,0),0) | AG4: =IF(AG$3,ROUND(J4,0),0) | AH4: =IF(AH$3,ROUND(K4,0),0) | AI4: =IF(AI$3,ROUND(L4,0),0) | AK4: =IF(AK$3,ROUND(D4,0),0) | AL4: =IF(AL$3,ROUND(E4,0),0) | AM4: =IF(AM$3,ROUND(F4,0),0) | AN4: =IF(AN$3,ROUND(G4,0),0) | AO4: =IF(AO$3,ROUND(H4,0),0) | AP4: =IF(AP$3,ROUND(I4,0),0) | AQ4: =IF(AQ$3,ROUND(J4,0),0) | AR4: =IF(AR$3,ROUND(K4,0),0) | AS4: =IF(AS$3,ROUND(L4,0),0)
