Workbook

Sheet 1040
A1: FILING STATUS | G1: 1099's | H1: Filing Status | I1: FED STANDARD | K1: AL EXCLUSION
A2: INCOME | B2: FED INCOME | C2: AL INCOME | D2: FED WH | E2: AL WH | F2: FICA | H2: TRUE | I2: SINGLE | J2: 15750 | K2: 1500
B3: 12300 | C3: 12300 | D3: 1476 | E3: 553.5 | F3: 940.95 | G3: 8750 | H3: FALSE | I3: MFJ/QSS | J3: 31500 | K3: 3000
B4: 68420 | C4: 68420 | D4: 8210.4 | E4: 3079 | F4: 5234.13 | H4: FALSE | I4: HOH | J4: 23625 | K4: 3000 | R4: HELPER CELLS DON’T CHANGE
H5: FALSE | I5: MFS | J5: 15750 | K5: 1500 | R5: Total Income w/o SSA | S5: Helper Cells
H6: FALSE | I6: SENIOR Single | J6: 17750 | K6: 1500 | R6: =SUM(B9:B24,B27:B40)-B43 | S6: =R6 + (A26/2)
H7: FALSE | I7: SENIOR MFJ/QSS | J7: 34700 | K7: 3000 | R7: AL | S7: 0.09
C8: 0 | H8: FALSE | I8: SENIOR HOH | J8: 25625 | K8: 3000
B9: =SUM(B3:B8) | C9: =SUM(C3:C8) | D9: =SUM(D3:D8) | E9: =SUM(E3:E8) | F9: =SUM(F3:F8) | G9: =SUM(G2:G8)
A11: INTEREST | B11: 342.18 | C11: 0
H13: QTY
H14: 0 | I14: Dependent Under 17 | J14: =H14*2200 | K14: =IF(C45<=50000,H14*1000,IF(C45<=100000,H14*500,H14*300))
H15: 0 | I15: Dependent Over 17 | J15: =H15*500 | K15: =IF(C45<=50000,H15*1000,IF(C45<=100000,H15*500,H15*300))
A16: DIVIDED | C16: =B16 | I16: Eligible Seniors
J19: AL ONLY | K19: FED | L19: ITEMIZED DEDUCTIONS
A20: IRA | C20: =B20 | G20: AL PENSION ADJ | H20: =SUM(B22:B24) | J20: =IF(O23>0,O23,0) | K20: =IF(P23>0,P23,0) | L20: MEDICAL | O20: Medical Deduction | P20: Medical Federal
A21: 401k | C21: =B21 | G21: AL Ex OT Wages | L21: GENERAL SALES TAX
A22: PENSION | L22: PROPERTY TAXES | O22: =C41*0.04 | P22: =B41*0.075
L23: VEHICLE CAR TAGS | O23: =O21-O22 | P23: =O21-P22
L24: OTHER TAX
A25: SOCIAL SECURITY | B25: =MIN(A26*0.85, IF(OR(H3,H7,H8), IF(S6<=32000,0, IF(S6<=44000,(S6-32000)*0.5,6000+(S6-44000)*0.85)), IF(OR(H2,H4,H6,H8), IF(S6<=25000,0, IF(S6<=34000,(S6-25000)*0.5,4500+(S6-34000)*0.85)), IF(H5, A26*0.85, 0)))) | C25: 0 | L25: MORTGAGE
A26: 0 | L26: CHARITY - CASH | O26: MISC
A27: K-1 INCOME | K27: 0 | L27: CHARITY-NONCASH
J28: =IF(O29>0,O29,0) | L28: MISC | O28: =C41*0.02
L29: LOCAL TAX | O29: =O27-O28
A30: OTHER | J30: =F9 | L30: FICA
A31: w2g | L31: PRIOR YEAR SE TAX
K32: =J30+K31+J20+K29+J28+K27+K26+K25+K24+K23+K22 | L32: Total AL Itemized Deductions
K33: =SUM(K20:K27) | L33: Total Fed Itemized Deductions
A36: CAPITAL GAIN/LOSS | B36: ='SCH D'!E32 | C36: =B36
A38: SCH C | B38: ='SCH C'!B27 | C38: ='SCH C'!B27
A39: SCH F
A40: SCH E | B40: ='SCH E'!B23 | C40: ='SCH E'!B23
A41: TOTAL INCOME | B41: =SUM(B9:B40) | C41: =SUM(C9:C40)
L42: AL Adjustments to Income
A43: Adjustments | C43: =M43 | L43: Contribution to 529 Plan | M43: =SUM(M42)
A45: Adjusted Gross Income | B45: =B41-B43 | C45: =C41-C43
A47: Deductions
A48: STANDARD | B48: =SUMIF(H2:H7,TRUE,J2:J7)
A49: ITEMIZED | C49: =K32
...

Sheet Sch 1 A Ded
A1: Modified AGI | B1: ='1040'!B41
A5: Qualified Tips | C5: On W2 | E5: On other documets
A6: Qualified Overtime | C6: On W2 | E6: On Last Pay Stub
A7: Car Loan Interest
A8: Senior Deduction | B8: =IF(IFERROR(VALUE('1040'!H16),0)>0, MAX(6000*IFERROR(VALUE('1040'!H16),0) - 0.06*MAX(B1-IF('1040'!H8<>"",150000,75000),0),0), 0)
B11: =SUM(B5:B8)

Sheet SCH C
A3: INCOME | B3: 8750
A6: EXPENSES
A7: Advertising
A8: Auto
A9: Commissions
A10: Contract Labor
A11: Depreciation
A12: Insurance
A13: Interest
A14: Legal/Professional
A15: Office
A16: Rent
A17: Repairs
... A24: Home Office
A25: TOTAL | B25: =SUM(B7:B24)
A27: Profit/Loss | B27: =B3-B25
A29: Tips Deduction

Sheet SCH D
B1: SHORT TERM
A2: ACCT NAME | B2: PROCEEDS | C2: BASIS | D2: WASH | E2: GAIN/LOSS
E3: =B3-C3+D3
B16: LONG TERM
A17: ACCT NAME | B17: PROCEEDS | C17: BASIS | D17: WASH | E17: GAIN/LOSS
E18: =B18-C18
A26: Total Stock Transactions | E26: =E18+E3
A28: Other Capital Gain Distributions
E31: =SUM(E29:E30)
A32: Total Gain/Loss | E32: =E26+E31

Sheet SCH E
A3: INCOME
A6: EXPENSES
A7: Auto
A8: Cleaning
A9: Commissions
A10: Insurance
A11: Legal/Professional
A12: Management
A13: Mortgage interest
A14: Repairs
A15: Remodeling
A16: Supplies
... A20: Other
A21: TOTAL | B21: =SUM(B7:B20)
A23: Profit/Loss | B23: =B3-B21

Sheet SCH F
